<?xml version="1.0" encoding="utf-8" ?>
<!-- This URDF was automatically created by SolidWorks to URDF Exporter! Originally created by Stephen Brawner (brawner@gmail.com) 
     Commit Version: 1.5.1-0-g916b5db  Build Version: 1.5.7152.31018
     For more information, please see http://wiki.ros.org/sw_urdf_exporter -->
<robot name="FR10-V5.0.SLDASM">
    <link name="base_link">
        
<inertial>
            <origin xyz="-0.00037779 0.035824 0.00035123" rpy="0 0 0" />
            <mass value="0.73773" />
            <inertia ixx="0.0026261" ixy="-8.5597E-06" ixz="-1.1085E-05" iyy="0.0044464" iyz="8.0719E-06" izz="0.0026257" />
        </inertial>

        <visual>
            <origin xyz="0 0 0" rpy="0 0 0" />
            <geometry>
                <mesh filename="package://frcobot_description/meshes/fr10/visual/base_link.DAE" />
            </geometry>
            <material name="">
                <color rgba="0.79216 0.81961 0.93333 1" />
            </material>
        </visual>
        <collision>
            <origin xyz="0 0 0" rpy="0 0 0" />
            <geometry>
                <mesh filename="package://frcobot_description/meshes/fr10/collision/base_link.STL" />
            </geometry>
        </collision>
    </link>
    <link name="shoulder_Link">
        
<inertial>
            <origin xyz="-1.0816E-07 -0.13473 -0.0047771" rpy="0 0 0" />
            <mass value="3.8977" />
            <inertia ixx="0.018741" ixy="5.0033E-08" ixz="9.2604E-08" iyy="0.012373" iyz="1.6387E-05" izz="0.018267" />
        </inertial>

        <visual>
            <origin xyz="0 0 0" rpy="0 3.14159 3.14159" />
            <geometry>
                <mesh filename="package://frcobot_description/meshes/fr10/visual/shoulder_Link.DAE" />
            </geometry>
            <material name="">
                <color rgba="0.79216 0.81961 0.93333 1" />
            </material>
        </visual>
        <collision>
            <origin xyz="0 0 0" rpy="0 0 0" />
            <geometry>
                <mesh filename="package://frcobot_description/meshes/fr10/collision/shoulder_Link.STL" />
            </geometry>
        </collision>
    </link>
    <joint name="j1" type="revolute">
        <origin xyz="0 0 0.045908" rpy="-1.5708 3.14159 3.14159" />
        <parent link="base_link" />
        <child link="shoulder_Link" />
        <axis xyz="0 1 0" />
        <limit lower="-3.0543261" upper="3.0543261" effort="150" velocity="3.15" />
        <calibration rising="0" falling="0" />
        <dynamics damping="0" friction="0" />
        <safety_controller soft_upper_limit="3.0543261" soft_lower_limit="-3.0543261" k_position="100.0" k_velocity="40.0" />
    </joint>
    <link name="upperarm_Link">
        
<inertial>
            <origin xyz="-1.2243E-07 0.28754 -0.13462" rpy="0 0 0" />
            <mass value="11.568" />
            <inertia ixx="0.18366" ixy="-1.1858E-08" ixz="8.4371E-08" iyy="0.03371" iyz="-8.597E-06" izz="0.17531" />
        </inertial>

        <visual>
            <origin xyz="0 0 0" rpy="0 0 0" />
            <geometry>
                <mesh filename="package://frcobot_description/meshes/fr10/visual/upperarm_Link.DAE" />
            </geometry>
            <material name="">
                <color rgba="0.79216 0.81961 0.93333 1" />
            </material>
        </visual>
        <collision>
            <origin xyz="0 0 0" rpy="0 0 0" />
            <geometry>
                <mesh filename="package://frcobot_description/meshes/fr10/collision/upperarm_Link.STL" />
            </geometry>
        </collision>
    </link>
    <joint name="j2" type="revolute">
        <origin xyz="0 0.134 -0.05" rpy="0 0 1.570793" />
        <parent link="shoulder_Link" />
        <child link="upperarm_Link" />
        <axis xyz="0 0 1" />
        <limit lower="-4.6251" upper="1.4835" effort="150" velocity="3.15" />
        <calibration rising="0" falling="0" />
        <dynamics damping="0" friction="0" />
        <safety_controller soft_upper_limit="1.4835298" soft_lower_limit="-4.6251225" k_position="100" k_velocity="40" />
    </joint>
    <link name="forearm_Link">
        
<inertial>
            <origin xyz="-7.3696E-07 0.42863 0.0061272" rpy="0 0 0" />
            <mass value="1.5774" />
            <inertia ixx="0.012832" ixy="-7.5164E-09" ixz="2.0819E-10" iyy="0.0031275" iyz="-8.569E-05" izz="0.01198" />
        </inertial>

        <visual>
            <origin xyz="0 0 0" rpy="0 3.14159 0" />
            <geometry>
                <mesh filename="package://frcobot_description/meshes/fr10/visual/forearm_Link.DAE" />
            </geometry>
            <material name="">
                <color rgba="0.79216 0.81961 0.93333 1" />
            </material>
        </visual>
        <collision>
            <origin xyz="0 0 0" rpy="0 0 0" />
            <geometry>
                <mesh filename="package://frcobot_description/meshes/fr10/collision/forearm_Link.STL" />
            </geometry>
        </collision>
    </link>
    <joint name="j3" type="revolute">
        <origin xyz="0 0.7 0.101" rpy="0 0 0" />
        <parent link="upperarm_Link" />
        <child link="forearm_Link" />
        <axis xyz="0 0 1" />
        <limit lower="-2.8274" upper="2.8274" effort="150" velocity="3.15" />
        <calibration rising="0" falling="0" />
        <dynamics damping="0" friction="0" />
        <safety_controller soft_upper_limit="2.8274" soft_lower_limit="-2.8274" k_position="100" k_velocity="40" />
    </joint>
    <link name="wrist1_Link">
        
<inertial>
            <origin xyz="1.119E-07 -0.0030015 0.074852" rpy="0 0 0" />
            <mass value="1.1074" />
            <inertia ixx="0.0019683" ixy="2.6898E-08" ixz="-6.9297E-09" iyy="0.0011013" iyz="3.8797E-06" izz="0.0020283" />
        </inertial>

        <visual>
            <origin xyz="0 0 0" rpy="0 0 0" />
            <!-- <origin
        xyz="0 0.268 -0.211"
        rpy="3.14159 0 0" /> -->
            <geometry>
                <mesh filename="package://frcobot_description/meshes/fr10/visual/wrist1_Link.DAE" />
            </geometry>
            <material name="">
                <color rgba="0.79216 0.81961 0.93333 1" />
            </material>
        </visual>
        <collision>
            <origin xyz="0 0 0" rpy="0 0 0" />
            <geometry>
                <mesh filename="package://frcobot_description/meshes/fr10/collision/wrist1_Link.STL" />
            </geometry>
        </collision>
    </link>
    <joint name="j4" type="revolute">
        <origin xyz="0 0.586 0.054" rpy="0 0 1.570793" />
        <parent link="forearm_Link" />
        <child link="wrist1_Link" />
        <axis xyz="0 0 1" />
        <limit lower="-4.6251" upper="1.4835" effort="28" velocity="3.2" />
        <calibration rising="0" falling="0" />
        <dynamics damping="0" friction="0" />
        <safety_controller soft_upper_limit="1.4835298" soft_lower_limit="-4.6251225" k_position="100" k_velocity="40" />
    </joint>
    <link name="wrist2_Link">
        
<inertial>
            <origin xyz="-0.058347 0.0037159 -0.0044844" rpy="0 0 0" />
            <mass value="0.89805" />
            <inertia ixx="0.0018083" ixy="3.8829E-06" ixz="-2.3592E-06" iyy="0.00097125" iyz="3.0557E-07" izz="0.0018386" />
        </inertial>

        <visual>
            <origin xyz="0 0 0" rpy="0 0 0" />
            <geometry>
                <mesh filename="package://frcobot_description/meshes/fr10/visual/wrist2_Link.DAE" />
            </geometry>
            <material name="">
                <color rgba="0.79216 0.81961 0.93333 1" />
            </material>
        </visual>
        <collision>
            <origin xyz="0 0 0" rpy="0 0 0" />
            <geometry>
                <mesh filename="package://frcobot_description/meshes/fr10/collision/wrist2_Link.STL" />
            </geometry>
        </collision>
    </link>
    <joint name="j5" type="revolute">
        <origin xyz="0 0.174 0.091" rpy="-1.5708 0 1.4981" />
        <parent link="wrist1_Link" />
        <child link="wrist2_Link" />
        <axis xyz="0.99706 0 0.076642" />
        <limit lower="-3.0543" upper="3.0543" effort="28" velocity="3.2" />
        <calibration rising="0" falling="0" />
        <dynamics damping="0" friction="0" />
        <safety_controller soft_upper_limit="3.0543261" soft_lower_limit="-3.0543261" k_position="100" k_velocity="40" />
    </joint>
    <link name="wrist3_Link">
        
<inertial>
            <origin xyz="-1.8098E-05 0.022586 -2.1629E-05" rpy="0 0 0" />
            <mass value="0.24186" />
            <inertia ixx="0.00015143" ixy="9.9865E-08" ixz="7.787E-08" iyy="0.00024022" iyz="6.6716E-08" izz="0.00015134" />
        </inertial>

        <visual>
            <origin xyz="0 0 0" rpy="0 0 0" />
            <geometry>
                <mesh filename="package://frcobot_description/meshes/fr10/visual/wrist3_Link.DAE" />
            </geometry>
            <material name="">
                <color rgba="0.79216 0.81961 0.93333 1" />
            </material>
        </visual>
        <collision>
            <origin xyz="0 0 0" rpy="0 0 0" />
            <geometry>
                <mesh filename="package://frcobot_description/meshes/fr10/collision/wrist3_Link.STL" />
            </geometry>
        </collision>
    </link>
    <joint name="j6" type="revolute">
        <origin xyz="-0.060457 -0.0602 -0.0046473" rpy="-3.1416 2.54 0" />
        <parent link="wrist2_Link" />
        <child link="wrist3_Link" />
        <axis xyz="0 1 0" />
        <limit lower="-3.0543" upper="3.0543" effort="28" velocity="3.2" />
        <calibration rising="0" falling="0" />
        <dynamics damping="0" friction="0" />
        <safety_controller soft_upper_limit="3.0543261" soft_lower_limit="-3.0543261" k_position="100" k_velocity="40" />
    </joint>
    
<transmission name="trans_j1">
        <type>transmission_interface/SimpleTransmission</type>
        <joint name="j1">
            <hardwareInterface>hardware_interface/PositionJointInterface</hardwareInterface>
        </joint>
        <actuator name="j1_motor">
            <hardwareInterface>hardware_interface/PositionJointInterface</hardwareInterface>
            <mechanicalReduction>1</mechanicalReduction>
        </actuator>
    </transmission>
    <transmission name="trans_j2">
        <type>transmission_interface/SimpleTransmission</type>
        <joint name="j2">
            <hardwareInterface>hardware_interface/PositionJointInterface</hardwareInterface>
        </joint>
        <actuator name="j2_motor">
            <hardwareInterface>hardware_interface/PositionJointInterface</hardwareInterface>
            <mechanicalReduction>1</mechanicalReduction>
        </actuator>
    </transmission>
    <transmission name="trans_j3">
        <type>transmission_interface/SimpleTransmission</type>
        <joint name="j3">
            <hardwareInterface>hardware_interface/PositionJointInterface</hardwareInterface>
        </joint>
        <actuator name="j3_motor">
            <hardwareInterface>hardware_interface/PositionJointInterface</hardwareInterface>
            <mechanicalReduction>1</mechanicalReduction>
        </actuator>
    </transmission>
    <transmission name="trans_j4">
        <type>transmission_interface/SimpleTransmission</type>
        <joint name="j4">
            <hardwareInterface>hardware_interface/PositionJointInterface</hardwareInterface>
        </joint>
        <actuator name="j4_motor">
            <hardwareInterface>hardware_interface/PositionJointInterface</hardwareInterface>
            <mechanicalReduction>1</mechanicalReduction>
        </actuator>
    </transmission>
    <transmission name="trans_j5">
        <type>transmission_interface/SimpleTransmission</type>
        <joint name="j5">
            <hardwareInterface>hardware_interface/PositionJointInterface</hardwareInterface>
        </joint>
        <actuator name="j5_motor">
            <hardwareInterface>hardware_interface/PositionJointInterface</hardwareInterface>
            <mechanicalReduction>1</mechanicalReduction>
        </actuator>
    </transmission>
    <transmission name="trans_j6">
        <type>transmission_interface/SimpleTransmission</type>
        <joint name="j6">
            <hardwareInterface>hardware_interface/PositionJointInterface</hardwareInterface>
        </joint>
        <actuator name="j6_motor">
            <hardwareInterface>hardware_interface/PositionJointInterface</hardwareInterface>
            <mechanicalReduction>1</mechanicalReduction>
        </actuator>
    </transmission>
    <gazebo>
        <plugin name="gazebo_ros_control" filename="libgazebo_ros_control.so">
            <robotNamespace>/</robotNamespace>
        </plugin>
    </gazebo>
</robot>