<?xml version="1.0" encoding="utf-8" ?>
<!-- This URDF was automatically created by SolidWorks to URDF Exporter! Originally created by Stephen Brawner (brawner@gmail.com) 
     Commit Version: 1.5.1-0-g916b5db  Build Version: 1.5.7152.31018
     For more information, please see http://wiki.ros.org/sw_urdf_exporter -->
<robot name="FR10-V5.0.SLDASM">
    <link name="world" />
    <joint name="world" type="fixed">
        <parent link="world" />
        <child link="base_link" />
    </joint>
    <link name="base_link">
        
        <inertial>
            <origin xyz="-0.00037779 0.035824 0.00035123" rpy="0 0 0" />
            <mass value="8.73773" />
            <inertia ixx="0.0026261" ixy="-8.5597E-06" ixz="-1.1085E-05" iyy="0.0044464" iyz="8.0719E-06" izz="0.0026257" />
        </inertial>

        <visual>
            <origin xyz="0 0 0" rpy="0 0 0" />
            <geometry>
                <mesh filename="package://frcobot_description/meshes/fr10/visual/base_link.DAE" />
            </geometry>
            <material name="">
                <color rgba="0.79216 0.81961 0.93333 1" />
            </material>
        </visual>
        <collision>
            <origin xyz="0 0 0" rpy="0 0 0" />
            <geometry>
                <mesh filename="package://frcobot_description/meshes/fr10/collision/base_link.STL" />
            </geometry>
        </collision>
    </link>
    <link name="shoulder_Link">
        
        <inertial>
            <origin xyz="-1.0816E-07 -0.13473 -0.0047771" rpy="0 0 0" />
            <mass value="3.8977" />
            <inertia ixx="0.018741" ixy="5.0033E-08" ixz="9.2604E-08" iyy="0.012373" iyz="1.6387E-05" izz="0.018267" />
        </inertial>

        <visual>
            <origin xyz="0 0 0" rpy="0 3.14159 3.14159" />
            <geometry>
                <mesh filename="package://frcobot_description/meshes/fr10/visual/shoulder_Link.DAE" />
            </geometry>
            <material name="">
                <color rgba="0.79216 0.81961 0.93333 1" />
            </material>
        </visual>
        <collision>
            <origin xyz="0.004 -0.045 -0.005" rpy="-1.57 0 0" />
            <geometry>
                <mesh filename="package://frcobot_description/meshes/fr10/collision/shoulder_Link.STL" />
            </geometry>
        </collision>
    </link>
    <joint name="j1" type="revolute">
        <origin xyz="0 0 0.045908" rpy="-1.5708 3.14159 3.14159" />
        <parent link="base_link" />
        <child link="shoulder_Link" />
        <axis xyz="0 1 0" />
        <limit lower="-3.0543261" upper="3.0543261" effort="150" velocity="3.15" />
        <calibration rising="0" falling="0" />
        <dynamics damping="0.05" friction="0.05" />
        <safety_controller soft_upper_limit="3.0543261" soft_lower_limit="-3.0543261" k_position="100.0" k_velocity="40.0" />
    </joint>
    <link name="upperarm_Link">
        
        <inertial>
            <origin xyz="-1.2243E-07 0.28754 -0.13462" rpy="0 0 0" />
            <mass value="11.568" />
            <inertia ixx="0.18366" ixy="-1.1858E-08" ixz="8.4371E-08" iyy="0.03371" iyz="-8.597E-06" izz="0.17531" />
        </inertial>

        <visual>
            <origin xyz="0 0 0" rpy="0 0 0" />
            <geometry>
                <mesh filename="package://frcobot_description/meshes/fr10/visual/upperarm_Link.DAE" />
            </geometry>
            <material name="">
                <color rgba="0.79216 0.81961 0.93333 1" />
            </material>
        </visual>
        <collision>
            <origin xyz="0 0 0.051" rpy="0 0 0" />
            <geometry>
                <mesh filename="package://frcobot_description/meshes/fr10/collision/upperarm_Link.STL" />
            </geometry>
        </collision>
    </link>
    <joint name="j2" type="revolute">
        <origin xyz="0 0.134 -0.05" rpy="0 0 1.570793" />
        <parent link="shoulder_Link" />
        <child link="upperarm_Link" />
        <axis xyz="0 0 1" />
        <limit lower="-4.6251" upper="1.4835" effort="150" velocity="3.15" />
        <calibration rising="0" falling="0" />
        <dynamics damping="0.05" friction="0.05" />
        <safety_controller soft_upper_limit="1.4835298" soft_lower_limit="-4.6251225" k_position="100" k_velocity="40" />
    </joint>
    <link name="forearm_Link">
        
        <inertial>
            <origin xyz="-7.3696E-07 0.42863 0.0061272" rpy="0 0 0" />
            <mass value="1.5774" />
            <inertia ixx="0.012832" ixy="-7.5164E-09" ixz="2.0819E-10" iyy="0.0031275" iyz="-8.569E-05" izz="0.01198" />
        </inertial>

        <visual>
            <origin xyz="0 0 0" rpy="0 3.14159 0" />
            <geometry>
                <mesh filename="package://frcobot_description/meshes/fr10/visual/forearm_Link.DAE" />
            </geometry>
            <material name="">
                <color rgba="0.79216 0.81961 0.93333 1" />
            </material>
        </visual>
        <collision>
            <origin xyz="0 0 -0.01" rpy="0 0 -1.57" />
            <geometry>
                <mesh filename="package://frcobot_description/meshes/fr10/collision/forearm_Link.STL" />
            </geometry>
        </collision>
    </link>
    <joint name="j3" type="revolute">
        <origin xyz="0 0.7 0.101" rpy="0 0 0" />
        <parent link="upperarm_Link" />
        <child link="forearm_Link" />
        <axis xyz="0 0 1" />
        <limit lower="-2.8274" upper="2.8274" effort="150" velocity="3.15" />
        <calibration rising="0" falling="0" />
        <dynamics damping="0.05" friction="0.05" />
        <safety_controller soft_upper_limit="2.8274" soft_lower_limit="-2.8274" k_position="100" k_velocity="40" />
    </joint>
    <link name="wrist1_Link">
        
        <inertial>
            <origin xyz="1.119E-07 -0.0030015 0.074852" rpy="0 0 0" />
            <mass value="1.1074" />
            <inertia ixx="0.0019683" ixy="2.6898E-08" ixz="-6.9297E-09" iyy="0.0011013" iyz="3.8797E-06" izz="0.0020283" />
        </inertial>

        <visual>
            <origin xyz="0 0 0" rpy="0 0 0" />
            <geometry>
                <mesh filename="package://frcobot_description/meshes/fr10/visual/wrist1_Link.DAE" />
            </geometry>
            <material name="">
                <color rgba="0.79216 0.81961 0.93333 1" />
            </material>
        </visual>
        <collision>
            <origin xyz="0 0 -0.06" rpy="0 0 -1.57" />
            <geometry>
                <mesh filename="package://frcobot_description/meshes/fr10/collision/wrist1_Link.STL" />
            </geometry>
        </collision>
    </link>
    <joint name="j4" type="revolute">
        <origin xyz="0 0.586 0.054" rpy="0 0 1.570793" />
        <parent link="forearm_Link" />
        <child link="wrist1_Link" />
        <axis xyz="0 0 1" />
        <limit lower="-4.6251" upper="1.4835" effort="28" velocity="3.2" />
        <calibration rising="0" falling="0" />
        <dynamics damping="0.05" friction="0.05" />
        <safety_controller soft_upper_limit="1.4835298" soft_lower_limit="-4.6251225" k_position="100" k_velocity="40" />
    </joint>
    <link name="wrist2_Link">
        
        <inertial>
            <origin xyz="-0.058347 0.0037159 -0.0044844" rpy="0 0 0" />
            <mass value="0.89805" />
            <inertia ixx="0.0018083" ixy="3.8829E-06" ixz="-2.3592E-06" iyy="0.00097125" iyz="3.0557E-07" izz="0.0018386" />
        </inertial>

        <visual>
            <origin xyz="0 0 0" rpy="0 0 0" />
            <geometry>
                <mesh filename="package://frcobot_description/meshes/fr10/visual/wrist2_Link.DAE" />
            </geometry>
            <material name="">
                <color rgba="0.79216 0.81961 0.93333 1" />
            </material>
        </visual>
        <collision>
            <origin xyz="-0.114 0 -0.008" rpy="0 -1.4981 3.14" />
            <geometry>
                <mesh filename="package://frcobot_description/meshes/fr10/collision/wrist2_Link_correct.stl" />
            </geometry>
        </collision>    
    </link>
    <joint name="j5" type="revolute">
        <origin xyz="0 0.174 0.091" rpy="-1.5708 0 1.4981" />
        <parent link="wrist1_Link" />
        <child link="wrist2_Link" />
        <axis xyz="0.99706 0 0.076642" />
        <limit lower="-3.0543" upper="3.0543" effort="28" velocity="3.2" />
        <calibration rising="0" falling="0" />
        <dynamics damping="0.05" friction="0.05" />
        <safety_controller soft_upper_limit="3.0543261" soft_lower_limit="-3.0543261" k_position="100" k_velocity="40" />
    </joint>
    <link name="wrist3_Link">
        
        <inertial>
            <origin xyz="-1.8098E-05 0.022586 -2.1629E-05" rpy="0 0 0" />
            <mass value="0.24186" />
            <inertia ixx="0.00015143" ixy="9.9865E-08" ixz="7.787E-08" iyy="0.00024022" iyz="6.6716E-08" izz="0.00015134" />
        </inertial>

        <visual>
            <origin xyz="0 0 0" rpy="0 0 0" />
            <geometry>
                <mesh filename="package://frcobot_description/meshes/fr10/visual/wrist3_Link.DAE" />
            </geometry>
            <material name="">
                <color rgba="0.79216 0.81961 0.93333 1" />
            </material>
        </visual>
        <collision>
            <origin xyz="0 0 0" rpy="-1.57 0 0" />
            <geometry>
                <mesh filename="package://frcobot_description/meshes/fr10/collision/wrist3_Link_correct.stl" />
            </geometry>
        </collision>
    </link>
    <joint name="j6" type="revolute">
        <origin xyz="-0.060457 -0.0602 -0.0046473" rpy="-3.1416 0 0" />
        <parent link="wrist2_Link" />
        <child link="wrist3_Link" />
        <axis xyz="0 1 0" />
        <limit lower="-3.0543" upper="3.0543" effort="28" velocity="0.2" />
        <calibration rising="0" falling="0" />
        <dynamics damping="0.05" friction="0.5" />
        <safety_controller soft_upper_limit="3.0543261" soft_lower_limit="-3.0543261" k_position="100" k_velocity="40" />
    </joint>
    
<transmission name="trans_j1">
        <type>transmission_interface/SimpleTransmission</type>
        <joint name="j1">
            <hardwareInterface>hardware_interface/PositionJointInterface</hardwareInterface>
        </joint>
        <actuator name="j1_motor">
            <hardwareInterface>hardware_interface/PositionJointInterface</hardwareInterface>
            <mechanicalReduction>1</mechanicalReduction>
        </actuator>
    </transmission>
    <transmission name="trans_j2">
        <type>transmission_interface/SimpleTransmission</type>
        <joint name="j2">
            <hardwareInterface>hardware_interface/PositionJointInterface</hardwareInterface>
        </joint>
        <actuator name="j2_motor">
            <hardwareInterface>hardware_interface/PositionJointInterface</hardwareInterface>
            <mechanicalReduction>1</mechanicalReduction>
        </actuator>
    </transmission>
    <transmission name="trans_j3">
        <type>transmission_interface/SimpleTransmission</type>
        <joint name="j3">
            <hardwareInterface>hardware_interface/PositionJointInterface</hardwareInterface>
        </joint>
        <actuator name="j3_motor">
            <hardwareInterface>hardware_interface/PositionJointInterface</hardwareInterface>
            <mechanicalReduction>1</mechanicalReduction>
        </actuator>
    </transmission>
    <transmission name="trans_j4">
        <type>transmission_interface/SimpleTransmission</type>
        <joint name="j4">
            <hardwareInterface>hardware_interface/PositionJointInterface</hardwareInterface>
        </joint>
        <actuator name="j4_motor">
            <hardwareInterface>hardware_interface/PositionJointInterface</hardwareInterface>
            <mechanicalReduction>1</mechanicalReduction>
        </actuator>
    </transmission>
    <transmission name="trans_j5">
        <type>transmission_interface/SimpleTransmission</type>
        <joint name="j5">
            <hardwareInterface>hardware_interface/PositionJointInterface</hardwareInterface>
        </joint>
        <actuator name="j5_motor">
            <hardwareInterface>hardware_interface/PositionJointInterface</hardwareInterface>
            <mechanicalReduction>1</mechanicalReduction>
        </actuator>
    </transmission>
    <transmission name="trans_j6">
        <type>transmission_interface/SimpleTransmission</type>
        <joint name="j6">
            <hardwareInterface>hardware_interface/PositionJointInterface</hardwareInterface>
        </joint>
        <actuator name="j6_motor">
            <hardwareInterface>hardware_interface/PositionJointInterface</hardwareInterface>
            <mechanicalReduction>1</mechanicalReduction>
        </actuator>
    </transmission>
    <gazebo>
        <plugin name="gazebo_ros_control" filename="libgazebo_ros_control.so">
            <robotNamespace>/</robotNamespace>
        </plugin>
    </gazebo>







    <link name="realsense_link">
        <origin xyz="0 0 0" rpy="0 0 0"/>

        <inertial>
            <origin xyz="0 0 0" rpy="0 0 0" />
            <mass value="0.14186" />
            <inertia ixx="0.00015143" ixy="9.9865E-08" ixz="7.787E-08" iyy="0.00024022" iyz="6.6716E-08" izz="0.00015134" />
        </inertial>
    </link>

    <joint name="realsense_joint" type="fixed">
        <parent link="wrist3_Link"/>
        <child link="realsense_link"/>
        <origin xyz="0 0.3 0" rpy="0 0 1.57"/>
    </joint>

    <gazebo reference="realsense_link">
        <sensor name="depth_camera" type="depth">
        <update_rate>30</update_rate>
        <camera>
            <horizontal_fov>1.02974</horizontal_fov>
            <image>
            <format>R8G8B8</format>
            <width>640</width>
            <height>480</height>
            </image>
            <clip>
            <near>0.5</near>
            <far>18</far>
            </clip>
        </camera>
        <plugin filename="libgazebo_ros_openni_kinect.so" name="camera_controller">
            <cameraName>camera</cameraName>
            <alwaysOn>true</alwaysOn>
            <updateRate>20</updateRate>
            <pointCloudCutoff>0.2</pointCloudCutoff>
            <pointCloudCutoffMax>20</pointCloudCutoffMax>
            <imageTopicName>rgb/image_raw</imageTopicName>
            <cameraInfoTopicName>rgb/camera_info</cameraInfoTopicName>
            <depthImageTopicName>depth/image_raw</depthImageTopicName>
            <depthImageCameraInfoTopicName>depth/camera_info</depthImageCameraInfoTopicName>
            <pointCloudTopicName>depth/points</pointCloudTopicName>
            <frameName>camera_link</frameName>
            <distortion_k1>0.0</distortion_k1>
            <distortion_k2>0.0</distortion_k2>
            <distortion_k3>0.0</distortion_k3>
            <distortion_t1>0.0</distortion_t1>
            <distortion_t2>0.0</distortion_t2>
        </plugin>
        </sensor>

    </gazebo>

    <!-- base -->
    <link name="rh_p12_rn_base">
        <collision>
        <origin xyz="0 0 0" rpy="0 0 0"/>
        <geometry>
            <mesh filename="package://frcobot_description/meshes/gripper//base.stl" scale="0.001 0.001 0.001"/>
        </geometry>
        </collision>

        <visual>
        <origin xyz="0 0 0" rpy="0 0 0"/>
        <geometry>
            <mesh filename="package://frcobot_description/meshes/gripper//base.stl" scale="0.001 0.001 0.001"/>
        </geometry>
        <material name="grey"/>
        </visual>

        <inertial>
        <origin xyz="0.000 0.000 0.032" rpy="0 0 0"/>
        <mass value="0.236"/>
        <!--<inertia ixx="0.00017" ixy="0.0" ixz="0.0" iyy="0.00011" iyz="0.0" izz="0.00017" />-->
            <inertia ixx="0.0001" ixy="0.0" ixz="0.0" iyy="0.0001" iyz="0.0" izz="0.0001" />
        </inertial>
    </link>

    <!-- Joint -->
    <joint name="rh_p12_rn" type="revolute">
        <parent link="rh_p12_rn_base"/>
        <child link="rh_p12_rn_r1"/>
        <origin xyz="0.0 0.008 0.048" rpy="0 0 0"/>
        <axis xyz="1 0 0"/>
        <limit lower="-3.0543" upper="3.0543" effort="28" velocity="0.002" />
        <calibration rising="0" falling="0" />
        <dynamics damping="0.05" friction="0.5" />
    </joint>

    <transmission name="tran_r1">
        <type>transmission_interface/SimpleTransmission</type>
        <joint name="rh_p12_rn">
        <hardwareInterface>hardware_interface/EffortJointInterface</hardwareInterface>
        </joint>
        <actuator name="motor_r1">
        <hardwareInterface>hardware_interface/EffortJointInterface</hardwareInterface>
        <mechanicalReduction>1</mechanicalReduction>
        </actuator>
    </transmission>

    <!-- rh_p12_rn_r1 -->
    <link name="rh_p12_rn_r1">
        <!-- <collision>
        <origin xyz="0 0 0" rpy="0 0 0"/>
        <geometry>
            <mesh filename="package://frcobot_description/meshes/gripper//r1.stl" scale="0.001 0.001 0.001"/>
        </geometry>
        </collision> -->

        <visual>
        <origin xyz="0 0 0" rpy="0 0 0"/>
        <geometry>
            <mesh filename="package://frcobot_description/meshes/gripper//r1.stl" scale="0.001 0.001 0.001"/>
        </geometry>
        <material name="grey"/>
        </visual>

        <inertial>
            <origin xyz="0.000 0.034 0.004" rpy="0 0 0"/>
            <mass value="0.068"/>
            <inertia ixx="0.00001" ixy="0.0" ixz="0.0" iyy="0.00001" iyz="0.0" izz="0.00001" />
        </inertial>
    </link>

    <!-- Right Joint 2 -->
    <joint name="rh_r2" type="fixed">
        <parent link="rh_p12_rn_r1"/>
        <child link="rh_p12_rn_r2"/>
        <origin xyz="0.0 0.0493634 0.0285" rpy="0 0 0"/>
        <axis xyz="-1 0 0"/>
        <limit lower="-3.0543" upper="3.0543" effort="28" velocity="0.002" />
        <calibration rising="0" falling="0" />
        <dynamics damping="0.05" friction="0.5" />
    </joint>

    <!-- <transmission name="tran_r2">
        <type>transmission_interface/SimpleTransmission</type>
        <joint name="rh_r2">
        <hardwareInterface>hardware_interface/EffortJointInterface</hardwareInterface>
        </joint>
        <actuator name="motor_r2">
        <hardwareInterface>hardware_interface/EffortJointInterface</hardwareInterface>
        <mechanicalReduction>1</mechanicalReduction>
        </actuator>
    </transmission> -->

    <!-- rh_p12_rn_r2 -->
    <link name="rh_p12_rn_r2">
        <collision>
        <origin xyz="0 0 0" rpy="0 0 0"/>
        <geometry>
            <mesh filename="package://frcobot_description/meshes/gripper//r2.stl" scale="0.001 0.001 0.001"/>
        </geometry>
        </collision>

        <visual>
        <origin xyz="0 0 0" rpy="0 0 0"/>
        <geometry>
            <mesh filename="package://frcobot_description/meshes/gripper//r2.stl" scale="0.001 0.001 0.001"/>
        </geometry>
        <material name="grey"/>
        </visual>

        <inertial>
            <origin xyz="0.000 0.006 0.011" rpy="0 0 0"/>
            <mass value="0.0022"/>
            <inertia ixx="0.00001" ixy="0.0" ixz="0.0" iyy="0.00001" iyz="0.0" izz="0.00001" />
        </inertial>
    </link>

    <!-- Left Joint 1 -->
    <joint name="rh_l1" type="revolute">
        <parent link="rh_p12_rn_base"/>
        <child link="rh_p12_rn_l1"/>
        <origin xyz="0.0 -0.008 0.048" rpy="0 0 0"/>
        <axis xyz="-1 0 0"/>
        <limit lower="-3.0543" upper="3.0543" effort="28" velocity="0.002" />
        <calibration rising="0" falling="0" />
        <dynamics damping="0.05" friction="0.5" />
    </joint>

    <transmission name="tran_l1">
        <type>transmission_interface/SimpleTransmission</type>
        <joint name="rh_l1">
        <hardwareInterface>hardware_interface/EffortJointInterface</hardwareInterface>
        </joint>
        <actuator name="motor_l1">
        <hardwareInterface>hardware_interface/EffortJointInterface</hardwareInterface>
        <mechanicalReduction>1</mechanicalReduction>
        </actuator>
    </transmission>

    <!-- rh_p12_rn_l1 -->
    <link name="rh_p12_rn_l1">
        <!-- <collision>
        <origin xyz="0 0 0" rpy="0 0 0"/>
        <geometry>
            <mesh filename="package://frcobot_description/meshes/gripper//l1.stl" scale="0.001 0.001 0.001"/>
        </geometry>
        </collision> -->

        <visual>
        <origin xyz="0 0 0" rpy="0 0 0"/>
        <geometry>
            <mesh filename="package://frcobot_description/meshes/gripper//l1.stl" scale="0.001 0.001 0.001"/>
        </geometry>
        <material name="grey"/>
        </visual>

        <inertial>
            <origin xyz="0.000 -0.034 0.004" rpy="0 0 0"/>
            <mass value="0.068"/>
            <inertia ixx="0.00001" ixy="0.0" ixz="0.0" iyy="0.00001" iyz="0.0" izz="0.00001" />
        </inertial>
    </link>

    <!-- Left Joint 2 -->
    <joint name="rh_l2" type="fixed">
        <parent link="rh_p12_rn_l1"/>
        <child link="rh_p12_rn_l2"/>
        <origin xyz="0.0 -0.0493634 0.0285" rpy="0 0 0"/>
        <axis xyz="1 0 0"/>
        <limit lower="-3.0543" upper="3.0543" effort="28" velocity="0.002" />
        <calibration rising="0" falling="0" />
        <dynamics damping="0.05" friction="0.5" />
    </joint>

    <!-- <transmission name="tran_l2">
        <type>transmission_interface/SimpleTransmission</type>
        <joint name="rh_l2">
        <hardwareInterface>hardware_interface/EffortJointInterface</hardwareInterface>
        </joint>
        <actuator name="motor_l2">
        <hardwareInterface>hardware_interface/EffortJointInterface</hardwareInterface>
        <mechanicalReduction>1</mechanicalReduction>
        </actuator>
    </transmission> -->

    <!-- rh_p12_rn_l2 -->
    <link name="rh_p12_rn_l2">
        <collision>
        <origin xyz="0 0 0" rpy="0 0 0"/>
        <geometry>
            <mesh filename="package://frcobot_description/meshes/gripper//l2.stl" scale="0.001 0.001 0.001"/>
        </geometry>
        </collision>

        <visual>
        <origin xyz="0 0 0" rpy="0 0 0"/>
        <geometry>
            <mesh filename="package://frcobot_description/meshes/gripper//l2.stl" scale="0.001 0.001 0.001"/>
        </geometry>
        <material name="grey"/>
        </visual>

        <inertial>
            <origin xyz="0.000 -0.006 0.011" rpy="0 0 0"/>
            <mass value="0.0022"/>
            <inertia ixx="0.00001" ixy="0.0" ixz="0.0" iyy="0.00001" iyz="0.0" izz="0.00001" />
        </inertial>
    </link>

    <joint name="ur3_gripper_joint" type="fixed">
        <parent link="wrist3_Link" />
        <child link = "rh_p12_rn_base" />
        <origin xyz="0 0.05 0" rpy="-1.57 0 0"/>
    </joint>

</robot>