<?xml version="1.0" encoding="utf-8" ?>
<!-- This URDF was automatically created by SolidWorks to URDF Exporter! Originally created by Stephen Brawner (brawner@gmail.com) 
     Commit Version: 1.5.1-0-g916b5db  Build Version: 1.5.7152.31018
     For more information, please see http://wiki.ros.org/sw_urdf_exporter -->
<robot name="fr10v6">
    <link name="world" />
    <joint name="world" type="fixed">
        <parent link="world" />
        <child link="base_link" />
    </joint>
    <link name="base_link">
        
<inertial>
            <origin xyz="-0.00037778 -0.00035367 0.035825" rpy="0 0 0" />
            <mass value="0.73775" />
            <inertia ixx="0.0026263" ixy="1.1085E-05" ixz="-8.5601E-06" iyy="0.0026258" iyz="-7.9868E-06" izz="0.0044466" />
        </inertial>

        <visual>
            <origin xyz="0 0 0" rpy="0 0 0" />
            <geometry>
                <mesh filename="package://frcobot_description/meshes/fr10v6/visual/base_link.DAE" />
            </geometry>
            <material name="">
                <color rgba="1 1 1 1" />
            </material>
        </visual>
        <collision>
            <origin xyz="0 0 0" rpy="0 0 0" />
            <geometry>
                <mesh filename="package://frcobot_description/meshes/fr10v6/collision/base_link.STL" />
            </geometry>
        </collision>
    </link>
    <link name="j1_Link">
        
<inertial>
            <origin xyz="3.3888E-09 -0.0079713 0.17311" rpy="0 0 0" />
            <mass value="9.8122" />
            <inertia ixx="0.041746" ixy="-1.8666E-07" ixz="-2.3424E-07" iyy="0.039088" iyz="0.00068462" izz="0.031895" />
        </inertial>

        <visual>
            <origin xyz="0 0 0" rpy="0 0 0" />
            <geometry>
                <mesh filename="package://frcobot_description/meshes/fr10v6/visual/j1_Link.DAE" />
            </geometry>
            <material name="">
                <color rgba="0.79216 0.81961 0.93333 1" />
            </material>
        </visual>
        <collision>
            <origin xyz="0 0 0" rpy="0 0 0" />
            <geometry>
                <mesh filename="package://frcobot_description/meshes/fr10v6/collision/j1_Link.STL" />
            </geometry>
        </collision>
    </link>
    <joint name="j1" type="revolute">
        <origin xyz="0 0 0" rpy="0 0 0" />
        <parent link="base_link" />
        <child link="j1_Link" />
        <axis xyz="0 0 1" />
        <limit lower="-3.0543" upper="3.0543" effort="150" velocity="3.15" />
        <calibration rising="0" falling="0" />
        <dynamics damping="0" friction="0" />
        <safety_controller soft_lower_limit="-3.0543" soft_upper_limit="3.0543" k_position="15" k_velocity="10" />
    </joint>
    <link name="j2_Link">
        
<inertial>
            <origin xyz="-0.28687 -1.3562E-08 0.18211" rpy="0 0 0" />
            <mass value="29.757" />
            <inertia ixx="0.0783" ixy="-2.6909E-06" ixz="0.0073888" iyy="2.0297" iyz="4.6352E-07" izz="2.0144" />
        </inertial>

        <visual>
            <origin xyz="0 0 0" rpy="0 0 0" />
            <geometry>
                <mesh filename="package://frcobot_description/meshes/fr10v6/visual/j2_Link.DAE" />
            </geometry>
            <material name="">
                <color rgba="0.29804 0.29804 0.29804 1" />
            </material>
        </visual>
        <collision>
            <origin xyz="0 0 0" rpy="0 0 0" />
            <geometry>
                <mesh filename="package://frcobot_description/meshes/fr10v6/collision/j2_Link.STL" />
            </geometry>
        </collision>
    </link>
    <joint name="j2" type="revolute">
        <origin xyz="0 0 0.18" rpy="1.5708 0 0" />
        <parent link="j1_Link" />
        <child link="j2_Link" />
        <axis xyz="0 0 1" />
        <limit lower="-4.6251" upper="1.4835" effort="150" velocity="3.15" />
        <calibration rising="0" falling="0" />
        <dynamics damping="0" friction="0" />
        <safety_controller soft_lower_limit="-4.6251" soft_upper_limit="1.4835" k_position="15" k_velocity="10" />
    </joint>
    <link name="j3_Link">
        
<inertial>
            <origin xyz="-0.29317 8.0463E-07 0.049055" rpy="0 0 0" />
            <mass value="12.684" />
            <inertia ixx="0.015471" ixy="-3.4743E-06" ixz="-0.010782" iyy="0.53044" iyz="-8.5034E-07" izz="0.52884" />
        </inertial>

        <visual>
            <origin xyz="0 0 0" rpy="0 0 0" />
            <geometry>
                <mesh filename="package://frcobot_description/meshes/fr10v6/visual/j3_Link.DAE" />
            </geometry>
            <material name="">
                <color rgba="1 1 1 1" />
            </material>
        </visual>
        <collision>
            <origin xyz="0 0 0" rpy="0 0 0" />
            <geometry>
                <mesh filename="package://frcobot_description/meshes/fr10v6/collision/j3_Link.STL" />
            </geometry>
        </collision>
    </link>
    <joint name="j3" type="revolute">
        <origin xyz="-0.7 0 0" rpy="0 0 0" />
        <parent link="j2_Link" />
        <child link="j3_Link" />
        <axis xyz="0 0 1" />
        <limit lower="-2.8274" upper="2.8274" effort="150" velocity="3.15" />
        <calibration rising="0" falling="0" />
        <dynamics damping="0" friction="0" />
        <safety_controller soft_lower_limit="-2.8274" soft_upper_limit="2.8274" k_position="15" k_velocity="10" />
    </joint>
    <link name="j4_Link">
        
<inertial>
            <origin xyz="5.5958E-07 -0.0024406 0.15369" rpy="0 0 0" />
            <mass value="2.234" />
            <inertia ixx="0.0034862" ixy="7.2564E-09" ixz="6.713E-08" iyy="0.0026647" iyz="5.1294E-05" izz="0.0032186" />
        </inertial>

        <visual>
            <origin xyz="0 0 0" rpy="0 0 0" />
            <geometry>
                <mesh filename="package://frcobot_description/meshes/fr10v6/visual/j4_Link.DAE" />
            </geometry>
            <material name="">
                <color rgba="1 1 1 1" />
            </material>
        </visual>
        <collision>
            <origin xyz="0 0 0" rpy="0 0 0" />
            <geometry>
                <mesh filename="package://frcobot_description/meshes/fr10v6/collision/j4_Link.STL" />
            </geometry>
        </collision>
    </link>
    <joint name="j4" type="revolute">
        <origin xyz="-0.586 0 0" rpy="0 0 0" />
        <parent link="j3_Link" />
        <child link="j4_Link" />
        <axis xyz="0 0 1" />
        <limit lower="-4.6251" upper="1.4835" effort="28" velocity="3.2" />
        <calibration rising="0" falling="0" />
        <dynamics damping="0" friction="0" />
        <safety_controller soft_lower_limit="-4.6251" soft_upper_limit="1.4835" k_position="15" k_velocity="10" />
    </joint>
    <link name="j5_Link">
        
<inertial>
            <origin xyz="-5.5958E-07 0.0024406 0.10869" rpy="0 0 0" />
            <mass value="2.234" />
            <inertia ixx="0.0034862" ixy="7.2564E-09" ixz="-6.713E-08" iyy="0.0026647" iyz="-5.1294E-05" izz="0.0032186" />
        </inertial>

        <visual>
            <origin xyz="0 0 0" rpy="0 0 0" />
            <geometry>
                <mesh filename="package://frcobot_description/meshes/fr10v6/visual/j5_Link.DAE" />
            </geometry>
            <material name="">
                <color rgba="1 1 1 1" />
            </material>
        </visual>
        <collision>
            <origin xyz="0 0 0" rpy="0 0 0" />
            <geometry>
                <mesh filename="package://frcobot_description/meshes/fr10v6/collision/j5_Link.STL" />
            </geometry>
        </collision>
    </link>
    <joint name="j5" type="revolute">
        <origin xyz="0 0 0.159" rpy="1.5708 0 0" />
        <parent link="j4_Link" />
        <child link="j5_Link" />
        <axis xyz="0 0 1" />
        <limit lower="-3.0543" upper="3.0543" effort="28" velocity="3.2" />
        <calibration rising="0" falling="0" />
        <dynamics damping="0" friction="0" />
        <safety_controller soft_lower_limit="-3.0543" soft_upper_limit="3.0543" k_position="15" k_velocity="10" />
    </joint>
    <link name="j6_Link">
        
<inertial>
            <origin xyz="-8.7069E-06 -3.2125E-05 0.082427" rpy="0 0 0" />
            <mass value="0.20143" />
            <inertia ixx="0.00011168" ixy="9.1307E-11" ixz="6.3345E-09" iyy="0.0001118" iyz="9.9205E-08" izz="0.00016774" />
        </inertial>

        <visual>
            <origin xyz="0 0 0" rpy="0 0 0" />
            <geometry>
                <mesh filename="package://frcobot_description/meshes/fr10v6/visual/j6_Link.DAE" />
            </geometry>
            <material name="">
                <color rgba="0.79216 0.81961 0.93333 1" />
            </material>
        </visual>
        <collision>
            <origin xyz="0 0 0" rpy="0 0 0" />
            <geometry>
                <mesh filename="package://frcobot_description/meshes/fr10v6/collision/j6_Link.STL" />
            </geometry>
        </collision>
    </link>
    <joint name="j6" type="revolute">
        <origin xyz="0 0 0.114" rpy="-1.5708 0 0" />
        <parent link="j5_Link" />
        <child link="j6_Link" />
        <axis xyz="0 0 1" />
        <limit lower="-3.0543" upper="3.0543" effort="28" velocity="3.2" />
        <calibration rising="0" falling="0" />
        <dynamics damping="0" friction="0" />
        <safety_controller soft_lower_limit="-3.0543" soft_upper_limit="3.0543" k_position="15" k_velocity="10" />
    </joint>
    <link name="tool_Link">
        
<inertial>
            <origin xyz="0.24412 0.079181 -0.126" rpy="0 0 0" />
            <mass value="0" />
            <inertia ixx="0.10666" ixy="-0.046059" ixz="0.046354" iyy="0.87967" iyz="0.0095222" izz="0.85231" />
        </inertial>

        <visual>
            <origin xyz="0 0 0" rpy="0 0 0" />
            <geometry>
                <mesh filename="package://frcobot_description/meshes/fr10v6/visual/tool_Link.STL" />
            </geometry>
            <material name="">
                <color rgba="1 1 1 1" />
            </material>
        </visual>
        <collision>
            <origin xyz="0 0 0" rpy="0 0 0" />
            <geometry>
                <mesh filename="package://frcobot_description/meshes/fr10v6/collision/tool_Link.STL" />
            </geometry>
        </collision>
    </link>
    <joint name="tool" type="fixed">
        <origin xyz="0 0 0.106" rpy="0 0 0" />
        <parent link="j6_Link" />
        <child link="tool_Link" />
        <axis xyz="0 0 1" />
        <limit lower="0" upper="0" effort="0" velocity="0" />
        <calibration rising="0" falling="0" />
        <dynamics damping="0" friction="0" />
        <safety_controller soft_lower_limit="0" soft_upper_limit="0" k_position="0" k_velocity="0" />
    </joint>
    
<transmission name="trans_j1">
        <type>transmission_interface/SimpleTransmission</type>
        <joint name="j1">
            <hardwareInterface>hardware_interface/PositionJointInterface</hardwareInterface>
        </joint>
        <actuator name="j1_motor">
            <hardwareInterface>hardware_interface/PositionJointInterface</hardwareInterface>
            <mechanicalReduction>1</mechanicalReduction>
        </actuator>
    </transmission>
    <transmission name="trans_j2">
        <type>transmission_interface/SimpleTransmission</type>
        <joint name="j2">
            <hardwareInterface>hardware_interface/PositionJointInterface</hardwareInterface>
        </joint>
        <actuator name="j2_motor">
            <hardwareInterface>hardware_interface/PositionJointInterface</hardwareInterface>
            <mechanicalReduction>1</mechanicalReduction>
        </actuator>
    </transmission>
    <transmission name="trans_j3">
        <type>transmission_interface/SimpleTransmission</type>
        <joint name="j3">
            <hardwareInterface>hardware_interface/PositionJointInterface</hardwareInterface>
        </joint>
        <actuator name="j3_motor">
            <hardwareInterface>hardware_interface/PositionJointInterface</hardwareInterface>
            <mechanicalReduction>1</mechanicalReduction>
        </actuator>
    </transmission>
    <transmission name="trans_j4">
        <type>transmission_interface/SimpleTransmission</type>
        <joint name="j4">
            <hardwareInterface>hardware_interface/PositionJointInterface</hardwareInterface>
        </joint>
        <actuator name="j4_motor">
            <hardwareInterface>hardware_interface/PositionJointInterface</hardwareInterface>
            <mechanicalReduction>1</mechanicalReduction>
        </actuator>
    </transmission>
    <transmission name="trans_j5">
        <type>transmission_interface/SimpleTransmission</type>
        <joint name="j5">
            <hardwareInterface>hardware_interface/PositionJointInterface</hardwareInterface>
        </joint>
        <actuator name="j5_motor">
            <hardwareInterface>hardware_interface/PositionJointInterface</hardwareInterface>
            <mechanicalReduction>1</mechanicalReduction>
        </actuator>
    </transmission>
    <transmission name="trans_j6">
        <type>transmission_interface/SimpleTransmission</type>
        <joint name="j6">
            <hardwareInterface>hardware_interface/PositionJointInterface</hardwareInterface>
        </joint>
        <actuator name="j6_motor">
            <hardwareInterface>hardware_interface/PositionJointInterface</hardwareInterface>
            <mechanicalReduction>1</mechanicalReduction>
        </actuator>
    </transmission>
    <gazebo>
        <plugin name="gazebo_ros_control" filename="libgazebo_ros_control.so">
            <robotNamespace>/</robotNamespace>
        </plugin>
    </gazebo>
</robot>