<?xml version="1.0" encoding="utf-8" ?>
<!-- This URDF was automatically created by SolidWorks to URDF Exporter! Originally created by Stephen Brawner (brawner@gmail.com) 
     Commit Version: 1.5.1-0-g916b5db  Build Version: 1.5.7152.31018
     For more information, please see http://wiki.ros.org/sw_urdf_exporter -->
<robot name="fr3v5">
    <link name="world" />
    <joint name="world" type="fixed">
        <parent link="world" />
        <child link="base_link" />
    </joint>
    <link name="base_link">
        
<inertial>
            <origin xyz="-0.0004939 -0.0004509 0.032214" rpy="0 0 0" />
            <mass value="0.77817" />
            <inertia ixx="0.0013699" ixy="1.1455E-05" ixz="-1.0521E-05" iyy="0.0013695" iyz="-9.7516E-06" izz="0.0019676" />
        </inertial>

        <visual>
            <origin xyz="0 0 0" rpy="0 0 0" />
            <geometry>
                <mesh filename="package://frcobot_description/meshes/fr3v5/visual/base_link.STL" />
            </geometry>
            <material name="">
                <color rgba="0.89804 0.91765 0.92941 1" />
            </material>
        </visual>
        <collision>
            <origin xyz="0 0 0" rpy="0 0 0" />
            <geometry>
                <mesh filename="package://frcobot_description/meshes/fr3v5/collision/base_link.STL" />
            </geometry>
        </collision>
    </link>
    <link name="shoulder_Link">
        
<inertial>
            <origin xyz="-6.9768E-07 -0.0021622 0.14153" rpy="0 0 0" />
            <mass value="2.24" />
            <inertia ixx="0.0047264" ixy="-5.1291E-08" ixz="-1.6678E-08" iyy="0.0046439" iyz="-3.3888E-06" izz="0.0025774" />
        </inertial>

        <visual>
            <origin xyz="0 0 0" rpy="0 0 0" />
            <geometry>
                <mesh filename="package://frcobot_description/meshes/fr3v5/visual/shoulder_Link.STL" />
            </geometry>
            <material name="">
                <color rgba="0.89804 0.91765 0.92941 1" />
            </material>
        </visual>
        <collision>
            <origin xyz="0 0 0" rpy="0 0 0" />
            <geometry>
                <mesh filename="package://frcobot_description/meshes/fr3v5/collision/shoulder_Link.STL" />
            </geometry>
        </collision>
    </link>
    <joint name="j1" type="revolute">
        <origin xyz="0 0 0" rpy="0 0 0" />
        <parent link="base_link" />
        <child link="shoulder_Link" />
        <axis xyz="0 0 1" />
        <limit lower="-3.0543" upper="3.0543" effort="150" velocity="3.15" />
        <calibration rising="0" falling="0" />
        <dynamics damping="0" friction="0" />
        <safety_controller soft_upper_limit="3.0543" soft_lower_limit="-3.0543" k_position="100.0" k_velocity="40.0" />
    </joint>
    <link name="upperarm_Link">
        
<inertial>
            <origin xyz="-0.14053 3.1983E-06 0.11612" rpy="0 0 0" />
            <mass value="4.94" />
            <inertia ixx="0.010088" ixy="1.8616E-06" ixz="-1.5931E-14" iyy="0.01143" iyz="-7.7907E-12" izz="0.0071309" />
        </inertial>

        <visual>
            <origin xyz="0 0 0" rpy="0 0 0" />
            <geometry>
                <mesh filename="package://frcobot_description/meshes/fr3v5/visual/upperarm_Link.STL" />
            </geometry>
            <material name="">
                <color rgba="0.89804 0.91765 0.92941 1" />
            </material>
        </visual>
        <collision>
            <origin xyz="0 0 0" rpy="0 0 0" />
            <geometry>
                <mesh filename="package://frcobot_description/meshes/fr3v5/collision/upperarm_Link.STL" />
            </geometry>
        </collision>
    </link>
    <joint name="j2" type="revolute">
        <origin xyz="0 0 0.1392" rpy="1.5708 0 -1.4405E-05" />
        <parent link="shoulder_Link" />
        <child link="upperarm_Link" />
        <axis xyz="0 0 1" />
        <limit lower="-4.6251" upper="1.4835" effort="150" velocity="3.15" />
        <calibration rising="0" falling="0" />
        <dynamics damping="0" friction="0" />
        <safety_controller soft_upper_limit="1.4835" soft_lower_limit="-4.6251" k_position="100.0" k_velocity="40.0" />
    </joint>
    <link name="forearm_Link">
        
<inertial>
            <origin xyz="-0.19264 4.9452E-06 3.3036E-05" rpy="0 0 0" />
            <mass value="2.29" />
            <inertia ixx="0.0035453" ixy="7.2272E-07" ixz="-7.3939E-05" iyy="0.0041768" iyz="-2.9234E-07" izz="0.0030346" />
        </inertial>

        <visual>
            <origin xyz="0 0 0" rpy="0 0 0" />
            <geometry>
                <mesh filename="package://frcobot_description/meshes/fr3v5/visual/forearm_Link.STL" />
            </geometry>
            <material name="">
                <color rgba="0.89804 0.91765 0.92941 1" />
            </material>
        </visual>
        <collision>
            <origin xyz="0 0 0" rpy="0 0 0" />
            <geometry>
                <mesh filename="package://frcobot_description/meshes/fr3v5/collision/forearm_Link.STL" />
            </geometry>
        </collision>
    </link>
    <joint name="j3" type="revolute">
        <origin xyz="-0.28 0 0" rpy="0 0 0" />
        <parent link="upperarm_Link" />
        <child link="forearm_Link" />
        <axis xyz="0 0 1" />
        <limit lower="-2.8274" upper="2.8274" effort="150" velocity="3.15" />
        <calibration rising="0" falling="0" />
        <dynamics damping="0" friction="0" />
        <safety_controller soft_upper_limit="2.8274" soft_lower_limit="-2.8274" k_position="100.0" k_velocity="40.0" />
    </joint>
    <link name="wrist1_Link">
        
<inertial>
            <origin xyz="4.2788E-07 0.001723 0.098605" rpy="0 0 0" />
            <mass value="1.56" />
            <inertia ixx="0.0027336" ixy="1.4344E-08" ixz="3.6288E-08" iyy="0.001585" iyz="-1.0107E-05" izz="0.0026273" />
        </inertial>

        <visual>
            <origin xyz="0 0 0" rpy="0 0 0" />
            <geometry>
                <mesh filename="package://frcobot_description/meshes/fr3v5/visual/wrist1_Link.STL" />
            </geometry>
            <material name="">
                <color rgba="0.89804 0.91765 0.92941 1" />
            </material>
        </visual>
        <collision>
            <origin xyz="0 0 0" rpy="0 0 0" />
            <geometry>
                <mesh filename="package://frcobot_description/meshes/fr3v5/collision/wrist1_Link.STL" />
            </geometry>
        </collision>
    </link>
    <joint name="j4" type="revolute">
        <origin xyz="-0.24001 0 0" rpy="0 0 0" />
        <parent link="forearm_Link" />
        <child link="wrist1_Link" />
        <axis xyz="0 0 1" />
        <limit lower="-4.6251" upper="1.4835" effort="28" velocity="3.2" />
        <calibration rising="0" falling="0" />
        <dynamics damping="0" friction="0" />
        <safety_controller soft_upper_limit="1.4835" soft_lower_limit="-4.6251" k_position="100.0" k_velocity="40.0" />
    </joint>
    <link name="wrist2_Link">
        
<inertial>
            <origin xyz="-4.3511E-07 -0.001723 0.098612" rpy="0 0 0" />
            <mass value="1.56" />
            <inertia ixx="0.0027336" ixy="1.4476E-08" ixz="-3.6276E-08" iyy="0.001585" iyz="1.0107E-05" izz="0.0026273" />
        </inertial>

        <visual>
            <origin xyz="0 0 0" rpy="0 0 0" />
            <geometry>
                <mesh filename="package://frcobot_description/meshes/fr3v5/visual/wrist2_Link.STL" />
            </geometry>
            <material name="">
                <color rgba="0.89804 0.91765 0.92941 1" />
            </material>
        </visual>
        <collision>
            <origin xyz="0 0 0" rpy="0 0 0" />
            <geometry>
                <mesh filename="package://frcobot_description/meshes/fr3v5/collision/wrist2_Link.STL" />
            </geometry>
        </collision>
    </link>
    <joint name="j5" type="revolute">
        <origin xyz="0 0 0.10199" rpy="1.5708 1.4405E-05 0" />
        <parent link="wrist1_Link" />
        <child link="wrist2_Link" />
        <axis xyz="0 0 1" />
        <limit lower="-3.0543" upper="3.0543" effort="28" velocity="3.2" />
        <calibration rising="0" falling="0" />
        <dynamics damping="0" friction="0" />
        <safety_controller soft_upper_limit="3.0543" soft_lower_limit="-3.0543" k_position="100.0" k_velocity="40.0" />
    </joint>
    <link name="wrist3_Link">
        
<inertial>
            <origin xyz="7.7503E-05 1.7913E-05 0.076124" rpy="0 0 0" />
            <mass value="0.36" />
            <inertia ixx="0.00055419" ixy="-3.0565E-09" ixz="-2.3684E-07" iyy="0.00055654" iyz="4.5224E-07" izz="0.00083168" />
        </inertial>

        <visual>
            <origin xyz="0 0 0" rpy="0 0 0" />
            <geometry>
                <mesh filename="package://frcobot_description/meshes/fr3v5/visual/wrist3_Link.STL" />
            </geometry>
            <material name="">
                <color rgba="0.89804 0.91765 0.92941 1" />
            </material>
        </visual>
        <collision>
            <origin xyz="0 0 0" rpy="0 0 0" />
            <geometry>
                <mesh filename="package://frcobot_description/meshes/fr3v5/collision/wrist3_Link.STL" />
            </geometry>
        </collision>
    </link>
    <joint name="j6" type="revolute">
        <origin xyz="0 0 0.102" rpy="-1.5708 0 0" />
        <parent link="wrist2_Link" />
        <child link="wrist3_Link" />
        <axis xyz="0 0 1" />
        <limit lower="-3.0543" upper="3.0543" effort="28" velocity="3.2" />
        <calibration rising="0" falling="0" />
        <dynamics damping="0" friction="0" />
        <safety_controller soft_upper_limit="3.0543" soft_lower_limit="-3.0543" k_position="100.0" k_velocity="40.0" />
    </joint>
    <link name="tool_Link">
        
<inertial>
            <origin xyz="0.24412 0.079181 -0.126" rpy="0 0 0" />
            <mass value="0" />
            <inertia ixx="0.10666" ixy="-0.046059" ixz="0.046354" iyy="0.87967" iyz="0.0095222" izz="0.85231" />
        </inertial>

        <visual>
            <origin xyz="0 0 0" rpy="0 0 0" />
            <geometry>
                <mesh filename="package://frcobot_description/meshes/fr3v5/visual/tool_Link.STL" />
            </geometry>
            <material name="">
                <color rgba="1 1 1 1" />
            </material>
        </visual>
        <collision>
            <origin xyz="0 0 0" rpy="0 0 0" />
            <geometry>
                <mesh filename="package://frcobot_description/meshes/fr3v5/collision/tool_Link.STL" />
            </geometry>
        </collision>
    </link>
    <joint name="tool" type="fixed">
        <origin xyz="0 -0.00038102 0.099" rpy="0 0 0" />
        <parent link="wrist3_Link" />
        <child link="tool_Link" />
        <axis xyz="0 0 0" />
        <limit lower="0" upper="0" effort="0" velocity="0" />
        <calibration rising="0" falling="0" />
        <dynamics damping="0" friction="0" />
        <safety_controller soft_upper_limit="0" soft_lower_limit="0" k_position="100.0" k_velocity="40.0" />
    </joint>
    
<transmission name="trans_j1">
        <type>transmission_interface/SimpleTransmission</type>
        <joint name="j1">
            <hardwareInterface>hardware_interface/PositionJointInterface</hardwareInterface>
        </joint>
        <actuator name="j1_motor">
            <hardwareInterface>hardware_interface/PositionJointInterface</hardwareInterface>
            <mechanicalReduction>1</mechanicalReduction>
        </actuator>
    </transmission>
    <transmission name="trans_j2">
        <type>transmission_interface/SimpleTransmission</type>
        <joint name="j2">
            <hardwareInterface>hardware_interface/PositionJointInterface</hardwareInterface>
        </joint>
        <actuator name="j2_motor">
            <hardwareInterface>hardware_interface/PositionJointInterface</hardwareInterface>
            <mechanicalReduction>1</mechanicalReduction>
        </actuator>
    </transmission>
    <transmission name="trans_j3">
        <type>transmission_interface/SimpleTransmission</type>
        <joint name="j3">
            <hardwareInterface>hardware_interface/PositionJointInterface</hardwareInterface>
        </joint>
        <actuator name="j3_motor">
            <hardwareInterface>hardware_interface/PositionJointInterface</hardwareInterface>
            <mechanicalReduction>1</mechanicalReduction>
        </actuator>
    </transmission>
    <transmission name="trans_j4">
        <type>transmission_interface/SimpleTransmission</type>
        <joint name="j4">
            <hardwareInterface>hardware_interface/PositionJointInterface</hardwareInterface>
        </joint>
        <actuator name="j4_motor">
            <hardwareInterface>hardware_interface/PositionJointInterface</hardwareInterface>
            <mechanicalReduction>1</mechanicalReduction>
        </actuator>
    </transmission>
    <transmission name="trans_j5">
        <type>transmission_interface/SimpleTransmission</type>
        <joint name="j5">
            <hardwareInterface>hardware_interface/PositionJointInterface</hardwareInterface>
        </joint>
        <actuator name="j5_motor">
            <hardwareInterface>hardware_interface/PositionJointInterface</hardwareInterface>
            <mechanicalReduction>1</mechanicalReduction>
        </actuator>
    </transmission>
    <transmission name="trans_j6">
        <type>transmission_interface/SimpleTransmission</type>
        <joint name="j6">
            <hardwareInterface>hardware_interface/PositionJointInterface</hardwareInterface>
        </joint>
        <actuator name="j6_motor">
            <hardwareInterface>hardware_interface/PositionJointInterface</hardwareInterface>
            <mechanicalReduction>1</mechanicalReduction>
        </actuator>
    </transmission>
    <gazebo>
        <plugin name="gazebo_ros_control" filename="libgazebo_ros_control.so">
            <robotNamespace>/</robotNamespace>
        </plugin>
    </gazebo>
</robot>
<?xml version="1.0" encoding="utf-8" ?>
<!-- This URDF was automatically created by SolidWorks to URDF Exporter! Originally created by Stephen Brawner (brawner@gmail.com) 
     Commit Version: 1.5.1-0-g916b5db  Build Version: 1.5.7152.31018
     For more information, please see http://wiki.ros.org/sw_urdf_exporter -->
<robot name="fr3v5">
    <link name="world" />
    <joint name="world" type="fixed">
        <parent link="world" />
        <child link="base_link" />
    </joint>
    <link name="base_link">
        
<inertial>
            <origin xyz="-0.0004939 -0.0004509 0.032214" rpy="0 0 0" />
            <mass value="0.77817" />
            <inertia ixx="0.0013699" ixy="1.1455E-05" ixz="-1.0521E-05" iyy="0.0013695" iyz="-9.7516E-06" izz="0.0019676" />
        </inertial>

        <visual>
            <origin xyz="0 0 0" rpy="0 0 0" />
            <geometry>
                <mesh filename="package://frcobot_description/meshes/fr3v5/visual/base_link.STL" />
            </geometry>
            <material name="">
                <color rgba="0.89804 0.91765 0.92941 1" />
            </material>
        </visual>
        <collision>
            <origin xyz="0 0 0" rpy="0 0 0" />
            <geometry>
                <mesh filename="package://frcobot_description/meshes/fr3v5/collision/base_link.STL" />
            </geometry>
        </collision>
    </link>
    <link name="shoulder_Link">
        
<inertial>
            <origin xyz="-6.9768E-07 -0.0021622 0.14153" rpy="0 0 0" />
            <mass value="2.24" />
            <inertia ixx="0.0047264" ixy="-5.1291E-08" ixz="-1.6678E-08" iyy="0.0046439" iyz="-3.3888E-06" izz="0.0025774" />
        </inertial>

        <visual>
            <origin xyz="0 0 0" rpy="0 0 0" />
            <geometry>
                <mesh filename="package://frcobot_description/meshes/fr3v5/visual/shoulder_Link.STL" />
            </geometry>
            <material name="">
                <color rgba="0.89804 0.91765 0.92941 1" />
            </material>
        </visual>
        <collision>
            <origin xyz="0 0 0" rpy="0 0 0" />
            <geometry>
                <mesh filename="package://frcobot_description/meshes/fr3v5/collision/shoulder_Link.STL" />
            </geometry>
        </collision>
    </link>
    <joint name="j1" type="revolute">
        <origin xyz="0 0 0" rpy="0 0 0" />
        <parent link="base_link" />
        <child link="shoulder_Link" />
        <axis xyz="0 0 1" />
        <limit lower="-3.0543" upper="3.0543" effort="150" velocity="3.15" />
        <calibration rising="0" falling="0" />
        <dynamics damping="0" friction="0" />
        <safety_controller soft_upper_limit="3.0543" soft_lower_limit="-3.0543" k_position="100.0" k_velocity="40.0" />
    </joint>
    <link name="upperarm_Link">
        
<inertial>
            <origin xyz="-0.14053 3.1983E-06 0.11612" rpy="0 0 0" />
            <mass value="4.94" />
            <inertia ixx="0.010088" ixy="1.8616E-06" ixz="-1.5931E-14" iyy="0.01143" iyz="-7.7907E-12" izz="0.0071309" />
        </inertial>

        <visual>
            <origin xyz="0 0 0" rpy="0 0 0" />
            <geometry>
                <mesh filename="package://frcobot_description/meshes/fr3v5/visual/upperarm_Link.STL" />
            </geometry>
            <material name="">
                <color rgba="0.89804 0.91765 0.92941 1" />
            </material>
        </visual>
        <collision>
            <origin xyz="0 0 0" rpy="0 0 0" />
            <geometry>
                <mesh filename="package://frcobot_description/meshes/fr3v5/collision/upperarm_Link.STL" />
            </geometry>
        </collision>
    </link>
    <joint name="j2" type="revolute">
        <origin xyz="0 0 0.1392" rpy="1.5708 0 -1.4405E-05" />
        <parent link="shoulder_Link" />
        <child link="upperarm_Link" />
        <axis xyz="0 0 1" />
        <limit lower="-4.6251" upper="1.4835" effort="150" velocity="3.15" />
        <calibration rising="0" falling="0" />
        <dynamics damping="0" friction="0" />
        <safety_controller soft_upper_limit="1.4835" soft_lower_limit="-4.6251" k_position="100.0" k_velocity="40.0" />
    </joint>
    <link name="forearm_Link">
        
<inertial>
            <origin xyz="-0.19264 4.9452E-06 3.3036E-05" rpy="0 0 0" />
            <mass value="2.29" />
            <inertia ixx="0.0035453" ixy="7.2272E-07" ixz="-7.3939E-05" iyy="0.0041768" iyz="-2.9234E-07" izz="0.0030346" />
        </inertial>

        <visual>
            <origin xyz="0 0 0" rpy="0 0 0" />
            <geometry>
                <mesh filename="package://frcobot_description/meshes/fr3v5/visual/forearm_Link.STL" />
            </geometry>
            <material name="">
                <color rgba="0.89804 0.91765 0.92941 1" />
            </material>
        </visual>
        <collision>
            <origin xyz="0 0 0" rpy="0 0 0" />
            <geometry>
                <mesh filename="package://frcobot_description/meshes/fr3v5/collision/forearm_Link.STL" />
            </geometry>
        </collision>
    </link>
    <joint name="j3" type="revolute">
        <origin xyz="-0.28 0 0" rpy="0 0 0" />
        <parent link="upperarm_Link" />
        <child link="forearm_Link" />
        <axis xyz="0 0 1" />
        <limit lower="-2.8274" upper="2.8274" effort="150" velocity="3.15" />
        <calibration rising="0" falling="0" />
        <dynamics damping="0" friction="0" />
        <safety_controller soft_upper_limit="2.8274" soft_lower_limit="-2.8274" k_position="100.0" k_velocity="40.0" />
    </joint>
    <link name="wrist1_Link">
        
<inertial>
            <origin xyz="4.2788E-07 0.001723 0.098605" rpy="0 0 0" />
            <mass value="1.56" />
            <inertia ixx="0.0027336" ixy="1.4344E-08" ixz="3.6288E-08" iyy="0.001585" iyz="-1.0107E-05" izz="0.0026273" />
        </inertial>

        <visual>
            <origin xyz="0 0 0" rpy="0 0 0" />
            <geometry>
                <mesh filename="package://frcobot_description/meshes/fr3v5/visual/wrist1_Link.STL" />
            </geometry>
            <material name="">
                <color rgba="0.89804 0.91765 0.92941 1" />
            </material>
        </visual>
        <collision>
            <origin xyz="0 0 0" rpy="0 0 0" />
            <geometry>
                <mesh filename="package://frcobot_description/meshes/fr3v5/collision/wrist1_Link.STL" />
            </geometry>
        </collision>
    </link>
    <joint name="j4" type="revolute">
        <origin xyz="-0.24001 0 0" rpy="0 0 0" />
        <parent link="forearm_Link" />
        <child link="wrist1_Link" />
        <axis xyz="0 0 1" />
        <limit lower="-4.6251" upper="1.4835" effort="28" velocity="3.2" />
        <calibration rising="0" falling="0" />
        <dynamics damping="0" friction="0" />
        <safety_controller soft_upper_limit="1.4835" soft_lower_limit="-4.6251" k_position="100.0" k_velocity="40.0" />
    </joint>
    <link name="wrist2_Link">
        
<inertial>
            <origin xyz="-4.3511E-07 -0.001723 0.098612" rpy="0 0 0" />
            <mass value="1.56" />
            <inertia ixx="0.0027336" ixy="1.4476E-08" ixz="-3.6276E-08" iyy="0.001585" iyz="1.0107E-05" izz="0.0026273" />
        </inertial>

        <visual>
            <origin xyz="0 0 0" rpy="0 0 0" />
            <geometry>
                <mesh filename="package://frcobot_description/meshes/fr3v5/visual/wrist2_Link.STL" />
            </geometry>
            <material name="">
                <color rgba="0.89804 0.91765 0.92941 1" />
            </material>
        </visual>
        <collision>
            <origin xyz="0 0 0" rpy="0 0 0" />
            <geometry>
                <mesh filename="package://frcobot_description/meshes/fr3v5/collision/wrist2_Link.STL" />
            </geometry>
        </collision>
    </link>
    <joint name="j5" type="revolute">
        <origin xyz="0 0 0.10199" rpy="1.5708 1.4405E-05 0" />
        <parent link="wrist1_Link" />
        <child link="wrist2_Link" />
        <axis xyz="0 0 1" />
        <limit lower="-3.0543" upper="3.0543" effort="28" velocity="3.2" />
        <calibration rising="0" falling="0" />
        <dynamics damping="0" friction="0" />
        <safety_controller soft_upper_limit="3.0543" soft_lower_limit="-3.0543" k_position="100.0" k_velocity="40.0" />
    </joint>
    <link name="wrist3_Link">
        
<inertial>
            <origin xyz="7.7503E-05 1.7913E-05 0.076124" rpy="0 0 0" />
            <mass value="0.36" />
            <inertia ixx="0.00055419" ixy="-3.0565E-09" ixz="-2.3684E-07" iyy="0.00055654" iyz="4.5224E-07" izz="0.00083168" />
        </inertial>

        <visual>
            <origin xyz="0 0 0" rpy="0 0 0" />
            <geometry>
                <mesh filename="package://frcobot_description/meshes/fr3v5/visual/wrist3_Link.STL" />
            </geometry>
            <material name="">
                <color rgba="0.89804 0.91765 0.92941 1" />
            </material>
        </visual>
        <collision>
            <origin xyz="0 0 0" rpy="0 0 0" />
            <geometry>
                <mesh filename="package://frcobot_description/meshes/fr3v5/collision/wrist3_Link.STL" />
            </geometry>
        </collision>
    </link>
    <joint name="j6" type="revolute">
        <origin xyz="0 0 0.102" rpy="-1.5708 0 0" />
        <parent link="wrist2_Link" />
        <child link="wrist3_Link" />
        <axis xyz="0 0 1" />
        <limit lower="-3.0543" upper="3.0543" effort="28" velocity="3.2" />
        <calibration rising="0" falling="0" />
        <dynamics damping="0" friction="0" />
        <safety_controller soft_upper_limit="3.0543" soft_lower_limit="-3.0543" k_position="100.0" k_velocity="40.0" />
    </joint>
    <link name="tool_Link">
        
<inertial>
            <origin xyz="0.24412 0.079181 -0.126" rpy="0 0 0" />
            <mass value="0" />
            <inertia ixx="0.10666" ixy="-0.046059" ixz="0.046354" iyy="0.87967" iyz="0.0095222" izz="0.85231" />
        </inertial>

        <visual>
            <origin xyz="0 0 0" rpy="0 0 0" />
            <geometry>
                <mesh filename="package://frcobot_description/meshes/fr3v5/visual/tool_Link.STL" />
            </geometry>
            <material name="">
                <color rgba="1 1 1 1" />
            </material>
        </visual>
        <collision>
            <origin xyz="0 0 0" rpy="0 0 0" />
            <geometry>
                <mesh filename="package://frcobot_description/meshes/fr3v5/collision/tool_Link.STL" />
            </geometry>
        </collision>
    </link>
    <joint name="tool" type="fixed">
        <origin xyz="0 -0.00038102 0.099" rpy="0 0 0" />
        <parent link="wrist3_Link" />
        <child link="tool_Link" />
        <axis xyz="0 0 0" />
        <limit lower="0" upper="0" effort="0" velocity="0" />
        <calibration rising="0" falling="0" />
        <dynamics damping="0" friction="0" />
        <safety_controller soft_upper_limit="0" soft_lower_limit="0" k_position="100.0" k_velocity="40.0" />
    </joint>
    
<transmission name="trans_j1">
        <type>transmission_interface/SimpleTransmission</type>
        <joint name="j1">
            <hardwareInterface>hardware_interface/PositionJointInterface</hardwareInterface>
        </joint>
        <actuator name="j1_motor">
            <hardwareInterface>hardware_interface/PositionJointInterface</hardwareInterface>
            <mechanicalReduction>1</mechanicalReduction>
        </actuator>
    </transmission>
    <transmission name="trans_j2">
        <type>transmission_interface/SimpleTransmission</type>
        <joint name="j2">
            <hardwareInterface>hardware_interface/PositionJointInterface</hardwareInterface>
        </joint>
        <actuator name="j2_motor">
            <hardwareInterface>hardware_interface/PositionJointInterface</hardwareInterface>
            <mechanicalReduction>1</mechanicalReduction>
        </actuator>
    </transmission>
    <transmission name="trans_j3">
        <type>transmission_interface/SimpleTransmission</type>
        <joint name="j3">
            <hardwareInterface>hardware_interface/PositionJointInterface</hardwareInterface>
        </joint>
        <actuator name="j3_motor">
            <hardwareInterface>hardware_interface/PositionJointInterface</hardwareInterface>
            <mechanicalReduction>1</mechanicalReduction>
        </actuator>
    </transmission>
    <transmission name="trans_j4">
        <type>transmission_interface/SimpleTransmission</type>
        <joint name="j4">
            <hardwareInterface>hardware_interface/PositionJointInterface</hardwareInterface>
        </joint>
        <actuator name="j4_motor">
            <hardwareInterface>hardware_interface/PositionJointInterface</hardwareInterface>
            <mechanicalReduction>1</mechanicalReduction>
        </actuator>
    </transmission>
    <transmission name="trans_j5">
        <type>transmission_interface/SimpleTransmission</type>
        <joint name="j5">
            <hardwareInterface>hardware_interface/PositionJointInterface</hardwareInterface>
        </joint>
        <actuator name="j5_motor">
            <hardwareInterface>hardware_interface/PositionJointInterface</hardwareInterface>
            <mechanicalReduction>1</mechanicalReduction>
        </actuator>
    </transmission>
    <transmission name="trans_j6">
        <type>transmission_interface/SimpleTransmission</type>
        <joint name="j6">
            <hardwareInterface>hardware_interface/PositionJointInterface</hardwareInterface>
        </joint>
        <actuator name="j6_motor">
            <hardwareInterface>hardware_interface/PositionJointInterface</hardwareInterface>
            <mechanicalReduction>1</mechanicalReduction>
        </actuator>
    </transmission>
    <gazebo>
        <plugin name="gazebo_ros_control" filename="libgazebo_ros_control.so">
            <robotNamespace>/frrobot</robotNamespace>
        </plugin>
    </gazebo>
</robot>