<?xml version="1.0" encoding="utf-8" ?>
<!-- This URDF was automatically created by SolidWorks to URDF Exporter! Originally created by Stephen Brawner (brawner@gmail.com) 
     Commit Version: 1.5.1-0-g916b5db  Build Version: 1.5.7152.31018
     For more information, please see http://wiki.ros.org/sw_urdf_exporter -->
<robot name="fr5v6">
    <link name="world" />
    <joint name="world" type="fixed">
        <parent link="world" />
        <child link="base_link" />
    </joint>
    <link name="base_link">
        
<inertial>
            <origin xyz="-0.00031896 -0.00029673 0.042463" rpy="0 0 0" />
            <mass value="1.6185" />
            <inertia ixx="0.0030836" ixy="1.5354E-05" ixz="-1.9315E-05" iyy="0.0030825" iyz="-1.7918E-05" izz="0.0045209" />
        </inertial>

        <visual>
            <origin xyz="0 0 0" rpy="0 0 0" />
            <geometry>
                <mesh filename="package://frcobot_description/meshes/fr5v6/visual/base_link.DAE" />
            </geometry>
            <material name="">
                <color rgba="0.89804 0.91765 0.92941 1" />
            </material>
        </visual>
        <collision>
            <origin xyz="0 0 0" rpy="0 0 0" />
            <geometry>
                <mesh filename="package://frcobot_description/meshes/fr5v6/collision/base_link.STL" />
            </geometry>
        </collision>
    </link>
    <link name="j1_Link">
        
<inertial>
            <origin xyz="5.0029E-07 -0.0040922 0.14629" rpy="0 0 0" />
            <mass value="4.3771" />
            <inertia ixx="0.010731" ixy="-8.0587E-09" ixz="-3.6773E-08" iyy="0.010408" iyz="0.00012853" izz="0.0081793" />
        </inertial>

        <visual>
            <origin xyz="0 0 0" rpy="0 0 0" />
            <geometry>
                <mesh filename="package://frcobot_description/meshes/fr5v6/visual/j1_Link.DAE" />
            </geometry>
            <material name="">
                <color rgba="0.89804 0.91765 0.92941 1" />
            </material>
        </visual>
        <collision>
            <origin xyz="0 0 0" rpy="0 0 0" />
            <geometry>
                <mesh filename="package://frcobot_description/meshes/fr5v6/collision/j1_Link.STL" />
            </geometry>
        </collision>
    </link>
    <joint name="j1" type="revolute">
        <origin xyz="0 0 0" rpy="0 0 0" />
        <parent link="base_link" />
        <child link="j1_Link" />
        <axis xyz="0 0 1" />
        <limit lower="-3.0543" upper="3.0543" effort="150" velocity="3.15" />
        <calibration rising="0" falling="0" />
        <dynamics damping="0" friction="0" />
        <safety_controller soft_lower_limit="-3.0543" soft_upper_limit="3.0543" k_position="15" k_velocity="10" />
    </joint>
    <link name="j2_Link">
        
<inertial>
            <origin xyz="-0.2125 -5.7643E-09 0.1346" rpy="0 0 0" />
            <mass value="14.458" />
            <inertia ixx="0.028392" ixy="-1.337E-07" ixz="-3.9895E-09" iyy="0.4559" iyz="4.214E-08" izz="0.44974" />
        </inertial>

        <visual>
            <origin xyz="0 0 0" rpy="0 0 0" />
            <geometry>
                <mesh filename="package://frcobot_description/meshes/fr5v6/visual/j2_Link.DAE" />
            </geometry>
            <material name="">
                <color rgba="0.89804 0.91765 0.92941 1" />
            </material>
        </visual>
        <collision>
            <origin xyz="0 0 0" rpy="0 0 0" />
            <geometry>
                <mesh filename="package://frcobot_description/meshes/fr5v6/collision/j2_Link.STL" />
            </geometry>
        </collision>
    </link>
    <joint name="j2" type="revolute">
        <origin xyz="0 0 0.152" rpy="1.5708 0 0" />
        <parent link="j1_Link" />
        <child link="j2_Link" />
        <axis xyz="0 0 1" />
        <limit lower="-4.6251" upper="1.4835" effort="150" velocity="3.15" />
        <calibration rising="0" falling="0" />
        <dynamics damping="0" friction="0" />
        <safety_controller soft_lower_limit="-4.6251" soft_upper_limit="1.4835" k_position="15" k_velocity="10" />
    </joint>
    <link name="j3_Link">
        
<inertial>
            <origin xyz="-0.18793 -8.4503E-07 0.0066357" rpy="0 0 0" />
            <mass value="7.6737" />
            <inertia ixx="0.0085096" ixy="2.1613E-06" ixz="-0.0068678" iyy="0.16971" iyz="3.7086E-08" izz="0.16854" />
        </inertial>

        <visual>
            <origin xyz="0 0 0" rpy="0 0 0" />
            <geometry>
                <mesh filename="package://frcobot_description/meshes/fr5v6/visual/j3_Link.DAE" />
            </geometry>
            <material name="">
                <color rgba="0.89804 0.91765 0.92941 1" />
            </material>
        </visual>
        <collision>
            <origin xyz="0 0 0" rpy="0 0 0" />
            <geometry>
                <mesh filename="package://frcobot_description/meshes/fr5v6/collision/j3_Link.STL" />
            </geometry>
        </collision>
    </link>
    <joint name="j3" type="revolute">
        <origin xyz="-0.425 0 0" rpy="0 0 0" />
        <parent link="j2_Link" />
        <child link="j3_Link" />
        <axis xyz="0 0 1" />
        <limit lower="-2.8274" upper="2.8274" effort="150" velocity="3.15" />
        <calibration rising="0" falling="0" />
        <dynamics damping="0" friction="0" />
        <safety_controller soft_lower_limit="-2.8274" soft_upper_limit="2.8274" k_position="15" k_velocity="10" />
    </joint>
    <link name="j4_Link">
        
<inertial>
            <origin xyz="4.98E-07 -0.003754 0.097155" rpy="0 0 0" />
            <mass value="1.6266" />
            <inertia ixx="0.00216" ixy="4.888E-09" ixz="3.1528E-08" iyy="0.0015455" iyz="3.7678E-05" izz="0.0019902" />
        </inertial>

        <visual>
            <origin xyz="0 0 0" rpy="0 0 0" />
            <geometry>
                <mesh filename="package://frcobot_description/meshes/fr5v6/visual/j4_Link.DAE" />
            </geometry>
            <material name="">
                <color rgba="0.89804 0.91765 0.92941 1" />
            </material>
        </visual>
        <collision>
            <origin xyz="0 0 0" rpy="0 0 0" />
            <geometry>
                <mesh filename="package://frcobot_description/meshes/fr5v6/collision/j4_Link.STL" />
            </geometry>
        </collision>
    </link>
    <joint name="j4" type="revolute">
        <origin xyz="-0.39501 0 0" rpy="0 0 0" />
        <parent link="j3_Link" />
        <child link="j4_Link" />
        <axis xyz="0 0 1" />
        <limit lower="-4.6251" upper="1.4835" effort="28" velocity="3.2" />
        <calibration rising="0" falling="0" />
        <dynamics damping="0" friction="0" />
        <safety_controller soft_lower_limit="-4.6251" soft_upper_limit="1.4835" k_position="15" k_velocity="10" />
    </joint>
    <link name="j5_Link">
        
<inertial>
            <origin xyz="-4.5588E-07 0.0038617 0.098257" rpy="0 0 0" />
            <mass value="1.5812" />
            <inertia ixx="0.0020612" ixy="8.7064E-09" ixz="-3.4742E-08" iyy="0.0014477" iyz="-2.8534E-05" izz="0.0019573" />
        </inertial>

        <visual>
            <origin xyz="0 0 0" rpy="0 0 0" />
            <geometry>
                <mesh filename="package://frcobot_description/meshes/fr5v6/visual/j5_Link.DAE" />
            </geometry>
            <material name="">
                <color rgba="0.89804 0.91765 0.92941 1" />
            </material>
        </visual>
        <collision>
            <origins xyz="0 0 0" rpy="0 0 0" />
            <geometry>
                <mesh filename="package://frcobot_description/meshes/fr5v6/collision/j5_Link.STL" />
            </geometry>
        </collision>
    </link>
    <joint name="j5" type="revolute">
        <origin xyz="0 0 0.1021" rpy="1.5708 0 0" />
        <parent link="j4_Link" />
        <child link="j5_Link" />
        <axis xyz="0 0 1" />
        <limit lower="-3.0543" upper="3.0543" effort="28" velocity="3.2" />
        <calibration rising="0" falling="0" />
        <dynamics damping="0" friction="0" />
        <safety_controller soft_lower_limit="-3.0543" soft_upper_limit="3.0543" k_position="15" k_velocity="10" />
    </joint>
    <link name="j6_Link">
        
<inertial>
            <origin xyz="7.7496E-05 1.7751E-05 0.076122" rpy="0 0 0" />
            <mass value="0.52542" />
            <inertia ixx="0.00027721" ixy="-1.8677E-09" ixz="-1.188E-07" iyy="0.00027839" iyz="2.2607E-07" izz="0.00041605" />
        </inertial>

        <visual>
            <origin xyz="0 0 0" rpy="0 0 0" />
            <geometry>
                <mesh filename="package://frcobot_description/meshes/fr5v6/visual/j6_Link.DAE" />
            </geometry>
            <material name="">
                <color rgba="0.89804 0.91765 0.92941 1" />
            </material>
        </visual>
        <collision>
            <origin xyz="0 0 0" rpy="0 0 0" />
            <geometry>
                <mesh filename="package://frcobot_description/meshes/fr5v6/collision/j6_Link.STL" />
            </geometry>
        </collision>
    </link>
    <joint name="j6" type="revolute">
        <origin xyz="0 0 0.102" rpy="-1.5708 0 0" />
        <parent link="j5_Link" />
        <child link="j6_Link" />
        <axis xyz="0 0 1" />
        <limit lower="-3.0543" upper="3.0543" effort="28" velocity="3.2" />
        <calibration rising="0" falling="0" />
        <dynamics damping="0" friction="0" />
        <safety_controller soft_lower_limit="-3.0543" soft_upper_limit="3.0543" k_position="15" k_velocity="10" />
    </joint>
    <link name="tool_Link">
        
<inertial>
            <origin xyz="0.24412 0.079181 -0.126" rpy="0 0 0" />
            <mass value="0" />
            <inertia ixx="0.10666" ixy="-0.046059" ixz="0.046354" iyy="0.87967" iyz="0.0095222" izz="0.85231" />
        </inertial>

        <visual>
            <origin xyz="0 0 0" rpy="0 0 0" />
            <geometry>
                <mesh filename="package://frcobot_description/meshes/fr5v6/visual/tool_Link.STL" />
            </geometry>
            <material name="">
                <color rgba="1 1 1 1" />
            </material>
        </visual>
        <collision>
            <origin xyz="0 0 0" rpy="0 0 0" />
            <geometry>
                <mesh filename="package://frcobot_description/meshes/fr5v6/collision/tool_Link.STL" />
            </geometry>
        </collision>
    </link>
    <joint name="tool" type="fixed">
        <origin xyz="0 0 0.1" rpy="0 0 0" />
        <parent link="j6_Link" />
        <child link="tool_Link" />
        <axis xyz="0 0 1" />
        <limit lower="0" upper="0" effort="0" velocity="0" />
        <calibration rising="0" falling="0" />
        <dynamics damping="0" friction="0" />
        <safety_controller soft_lower_limit="0" soft_upper_limit="0" k_position="0" k_velocity="0" />
    </joint>
    
<transmission name="trans_j1">
        <type>transmission_interface/SimpleTransmission</type>
        <joint name="j1">
            <hardwareInterface>hardware_interface/PositionJointInterface</hardwareInterface>
        </joint>
        <actuator name="j1_motor">
            <hardwareInterface>hardware_interface/PositionJointInterface</hardwareInterface>
            <mechanicalReduction>1</mechanicalReduction>
        </actuator>
    </transmission>
    <transmission name="trans_j2">
        <type>transmission_interface/SimpleTransmission</type>
        <joint name="j2">
            <hardwareInterface>hardware_interface/PositionJointInterface</hardwareInterface>
        </joint>
        <actuator name="j2_motor">
            <hardwareInterface>hardware_interface/PositionJointInterface</hardwareInterface>
            <mechanicalReduction>1</mechanicalReduction>
        </actuator>
    </transmission>
    <transmission name="trans_j3">
        <type>transmission_interface/SimpleTransmission</type>
        <joint name="j3">
            <hardwareInterface>hardware_interface/PositionJointInterface</hardwareInterface>
        </joint>
        <actuator name="j3_motor">
            <hardwareInterface>hardware_interface/PositionJointInterface</hardwareInterface>
            <mechanicalReduction>1</mechanicalReduction>
        </actuator>
    </transmission>
    <transmission name="trans_j4">
        <type>transmission_interface/SimpleTransmission</type>
        <joint name="j4">
            <hardwareInterface>hardware_interface/PositionJointInterface</hardwareInterface>
        </joint>
        <actuator name="j4_motor">
            <hardwareInterface>hardware_interface/PositionJointInterface</hardwareInterface>
            <mechanicalReduction>1</mechanicalReduction>
        </actuator>
    </transmission>
    <transmission name="trans_j5">
        <type>transmission_interface/SimpleTransmission</type>
        <joint name="j5">
            <hardwareInterface>hardware_interface/PositionJointInterface</hardwareInterface>
        </joint>
        <actuator name="j5_motor">
            <hardwareInterface>hardware_interface/PositionJointInterface</hardwareInterface>
            <mechanicalReduction>1</mechanicalReduction>
        </actuator>
    </transmission>
    <transmission name="trans_j6">
        <type>transmission_interface/SimpleTransmission</type>
        <joint name="j6">
            <hardwareInterface>hardware_interface/PositionJointInterface</hardwareInterface>
        </joint>
        <actuator name="j6_motor">
            <hardwareInterface>hardware_interface/PositionJointInterface</hardwareInterface>
            <mechanicalReduction>1</mechanicalReduction>
        </actuator>
    </transmission>
    <gazebo>
        <plugin name="gazebo_ros_control" filename="libgazebo_ros_control.so">
            <robotNamespace>/</robotNamespace>
        </plugin>
    </gazebo>
</robot>
